<?xml version="1.0"?>

<robot xmlns:xacro="http://ros.org/wiki/xacro">


    <xacro:macro name="rotating_velodyne" params="name parent *origin ros_topic update_rate ray_count min_angle max_angle">
<joint name="${name}_velodyne_joint" type="continuous">
    <axis xyz="0 0 1"/>
    <limit effort="100" velocity="100" />
    <joint_properties damping="0.7"/>
    <origin xyz="0.0 0.0 0.05967" rpy="0 0 1"/>
    <parent link="${name}_velodyne_base"/>
    <child link="${name}_velodyne_top"/>
  </joint>



      <joint name="${name}_joint" type="fixed">
        <xacro:insert_block name="origin" />
        <parent link="${parent}"/>
        <child link="${name}_velodyne_base"/>
      </joint>

      <link name="${name}_velodyne_base">
        <inertial>
          <mass value="1" />
          <origin xyz="0 0 0.029335" rpy="0 0 0" />
          <inertia ixx="0.001087473" ixy="0" ixz="0" iyy="0.001087473" iyz="0" izz="0.001092437" />
        </inertial>
        <visual>
          <origin xyz="0 0 -0.029335" rpy="0 0 0" />
          <geometry>
          <mesh filename="package://setup/meshes/velodyne/velodyne_base.dae"/>
        </geometry>
        </visual>
        <collision>
          <origin xyz="0 0 -0.0115" rpy="0 0 0" />
          <geometry>
          <cylinder radius="0.04267" length="0.05867" />
        </geometry>
        </collision>
      </link>

 <link name="${name}_velodyne_top">
        <inertial>
          <mass value="0.1" />
          <origin xyz="0 0 0.095455" rpy="0 0 0" />
          <inertia ixx="0.000090623" ixy="0" ixz="0" iyy="0.000090623" iyz="0" izz="0.000091036" />
        </inertial>
        <visual>
          <origin xyz="0 0 -0.0376785" rpy="0 0 1.5707" />
          <geometry>
          <mesh filename="package://setup/meshes/velodyne/velodyne_top.dae"/>
        </geometry>
        </visual>
        <collision>
          <origin xyz="0 0 -0.0115" rpy="0 0 0" />
          <geometry>
          <cylinder radius="0.04267" length="0.07357" />
        </geometry>
        </collision>
      </link>


      <gazebo reference="${name}_velodyne_top">
        <sensor type="ray" name="${name}">
          <always_on>true</always_on>
          <update_rate>${update_rate}</update_rate>
          <pose>0 0 0 0 0 0</pose>
          <visualize>true</visualize>
          <ray>
            <scan>
              <horizontal>
                <samples>${ray_count}</samples>
                <resolution>1</resolution>
                <min_angle>${min_angle * M_PI/180}</min_angle>
                <max_angle>${max_angle * M_PI/180}</max_angle>
              </horizontal>
            </scan>
            <range>
              <min>0.08</min>
              <max>30.0</max>
              <resolution>0.01</resolution>
            </range>
          </ray>
          <plugin name="gazebo_ros_${name}_controller" filename="libgazebo_ros_laser.so">
            <gaussianNoise>0.005</gaussianNoise>
            <alwaysOn>true</alwaysOn>
            <updateRate>${update_rate}</updateRate>
            <topicName>${ros_topic}</topicName>
            <frameName>${name}_velodyne_top</frameName>
          </plugin>
        </sensor>
      </gazebo>
      
<gazebo>
<plugin name="velodyne_control" filename="package://p3at_plugin/velodyne_plugin/libvelodyne_plugin.so">
  <velocity>0.4</velocity>
</plugin>

</gazebo>

    </xacro:macro>
  </robot>
  
